[2022-03-09 00:01:28,533: WARNING]: [discord.client]: PyNaCl is not installed, voice will NOT be supported
[2022-03-09 00:01:33,022: INFO]: [discord.client]: logging in using static token
[2022-03-09 00:01:33,998: INFO]: [discord.gateway]: Shard ID None has sent the IDENTIFY payload.
[2022-03-09 00:01:34,316: INFO]: [discord.gateway]: Shard ID None has connected to Gateway: ["gateway-prd-main-q2sk",{"micros":123181,"calls":["discord-sessions-blue-prd-2-90",{"micros":122329,"calls":["start_session",{"micros":103729,"calls":["discord-api-c4585754c-9h788",{"micros":93017,"calls":["get_user",{"micros":11900},"add_authorized_ip",{"micros":5455},"get_guilds",{"micros":24531},"coros_wait",{"micros":1}]}]},"guilds_connect",{"micros":2,"calls":[]},"presence_connect",{"micros":1,"calls":[]}]}]}] (Session ID: f2d619de0d8a8bafa4e8c6f447701784).
[2022-03-09 00:08:04,248: INFO]: [discord.gateway]: Timed out receiving packet. Attempting a reconnect.
[2022-03-09 00:08:04,248: INFO]: [discord.client]: Got a request to RESUME the websocket.
[2022-03-09 00:08:25,287: ERROR]: [discord.client]: Attempting a reconnect in 1.64s
Traceback (most recent call last):
  File "C:\Users\esaha\PycharmProjects\GIt\DiscordBot\venv\lib\site-packages\aiohttp\connector.py", line 986, in _wrap_create_connection
    return await self._loop.create_connection(*args, **kwargs)  # type: ignore[return-value]  # noqa
  File "C:\Users\esaha\AppData\Local\Programs\Python\Python39\lib\asyncio\base_events.py", line 1056, in create_connection
    raise exceptions[0]
  File "C:\Users\esaha\AppData\Local\Programs\Python\Python39\lib\asyncio\base_events.py", line 1041, in create_connection
    sock = await self._connect_sock(
  File "C:\Users\esaha\AppData\Local\Programs\Python\Python39\lib\asyncio\base_events.py", line 955, in _connect_sock
    await self.sock_connect(sock, address)
  File "C:\Users\esaha\AppData\Local\Programs\Python\Python39\lib\asyncio\proactor_events.py", line 702, in sock_connect
    return await self._proactor.connect(sock, address)
  File "C:\Users\esaha\AppData\Local\Programs\Python\Python39\lib\asyncio\windows_events.py", line 812, in _poll
    value = callback(transferred, key, ov)
  File "C:\Users\esaha\AppData\Local\Programs\Python\Python39\lib\asyncio\windows_events.py", line 599, in finish_connect
    ov.getresult()
OSError: [WinError 121] The semaphore timeout period has expired

The above exception was the direct cause of the following exception:

Traceback (most recent call last):
  File "C:\Users\esaha\PycharmProjects\GIt\DiscordBot\venv\lib\site-packages\discord\client.py", line 550, in connect
    self.ws = await asyncio.wait_for(coro, timeout=60.0)
  File "C:\Users\esaha\AppData\Local\Programs\Python\Python39\lib\asyncio\tasks.py", line 481, in wait_for
    return fut.result()
  File "C:\Users\esaha\PycharmProjects\GIt\DiscordBot\venv\lib\site-packages\discord\gateway.py", line 329, in from_client
    gateway = gateway or await client.http.get_gateway()
  File "C:\Users\esaha\PycharmProjects\GIt\DiscordBot\venv\lib\site-packages\discord\http.py", line 2453, in get_gateway
    data = await self.request(Route("GET", "/gateway"))
  File "C:\Users\esaha\PycharmProjects\GIt\DiscordBot\venv\lib\site-packages\discord\http.py", line 282, in request
    async with self.__session.request(method, url, **kwargs) as response:
  File "C:\Users\esaha\PycharmProjects\GIt\DiscordBot\venv\lib\site-packages\aiohttp\client.py", line 1138, in __aenter__
    self._resp = await self._coro
  File "C:\Users\esaha\PycharmProjects\GIt\DiscordBot\venv\lib\site-packages\aiohttp\client.py", line 535, in _request
    conn = await self._connector.connect(
  File "C:\Users\esaha\PycharmProjects\GIt\DiscordBot\venv\lib\site-packages\aiohttp\connector.py", line 542, in connect
    proto = await self._create_connection(req, traces, timeout)
  File "C:\Users\esaha\PycharmProjects\GIt\DiscordBot\venv\lib\site-packages\aiohttp\connector.py", line 907, in _create_connection
    _, proto = await self._create_direct_connection(req, traces, timeout)
  File "C:\Users\esaha\PycharmProjects\GIt\DiscordBot\venv\lib\site-packages\aiohttp\connector.py", line 1206, in _create_direct_connection
    raise last_exc
  File "C:\Users\esaha\PycharmProjects\GIt\DiscordBot\venv\lib\site-packages\aiohttp\connector.py", line 1175, in _create_direct_connection
    transp, proto = await self._wrap_create_connection(
  File "C:\Users\esaha\PycharmProjects\GIt\DiscordBot\venv\lib\site-packages\aiohttp\connector.py", line 992, in _wrap_create_connection
    raise client_error(req.connection_key, exc) from exc
aiohttp.client_exceptions.ClientConnectorError: Cannot connect to host discord.com:443 ssl:default [The semaphore timeout period has expired]
[2022-03-09 00:08:48,003: ERROR]: [discord.client]: Attempting a reconnect in 2.06s
Traceback (most recent call last):
  File "C:\Users\esaha\PycharmProjects\GIt\DiscordBot\venv\lib\site-packages\aiohttp\connector.py", line 986, in _wrap_create_connection
    return await self._loop.create_connection(*args, **kwargs)  # type: ignore[return-value]  # noqa
  File "C:\Users\esaha\AppData\Local\Programs\Python\Python39\lib\asyncio\base_events.py", line 1056, in create_connection
    raise exceptions[0]
  File "C:\Users\esaha\AppData\Local\Programs\Python\Python39\lib\asyncio\base_events.py", line 1041, in create_connection
    sock = await self._connect_sock(
  File "C:\Users\esaha\AppData\Local\Programs\Python\Python39\lib\asyncio\base_events.py", line 955, in _connect_sock
    await self.sock_connect(sock, address)
  File "C:\Users\esaha\AppData\Local\Programs\Python\Python39\lib\asyncio\proactor_events.py", line 702, in sock_connect
    return await self._proactor.connect(sock, address)
  File "C:\Users\esaha\AppData\Local\Programs\Python\Python39\lib\asyncio\windows_events.py", line 812, in _poll
    value = callback(transferred, key, ov)
  File "C:\Users\esaha\AppData\Local\Programs\Python\Python39\lib\asyncio\windows_events.py", line 599, in finish_connect
    ov.getresult()
OSError: [WinError 121] The semaphore timeout period has expired

The above exception was the direct cause of the following exception:

Traceback (most recent call last):
  File "C:\Users\esaha\PycharmProjects\GIt\DiscordBot\venv\lib\site-packages\discord\client.py", line 550, in connect
    self.ws = await asyncio.wait_for(coro, timeout=60.0)
  File "C:\Users\esaha\AppData\Local\Programs\Python\Python39\lib\asyncio\tasks.py", line 481, in wait_for
    return fut.result()
  File "C:\Users\esaha\PycharmProjects\GIt\DiscordBot\venv\lib\site-packages\discord\gateway.py", line 329, in from_client
    gateway = gateway or await client.http.get_gateway()
  File "C:\Users\esaha\PycharmProjects\GIt\DiscordBot\venv\lib\site-packages\discord\http.py", line 2453, in get_gateway
    data = await self.request(Route("GET", "/gateway"))
  File "C:\Users\esaha\PycharmProjects\GIt\DiscordBot\venv\lib\site-packages\discord\http.py", line 282, in request
    async with self.__session.request(method, url, **kwargs) as response:
  File "C:\Users\esaha\PycharmProjects\GIt\DiscordBot\venv\lib\site-packages\aiohttp\client.py", line 1138, in __aenter__
    self._resp = await self._coro
  File "C:\Users\esaha\PycharmProjects\GIt\DiscordBot\venv\lib\site-packages\aiohttp\client.py", line 535, in _request
    conn = await self._connector.connect(
  File "C:\Users\esaha\PycharmProjects\GIt\DiscordBot\venv\lib\site-packages\aiohttp\connector.py", line 542, in connect
    proto = await self._create_connection(req, traces, timeout)
  File "C:\Users\esaha\PycharmProjects\GIt\DiscordBot\venv\lib\site-packages\aiohttp\connector.py", line 907, in _create_connection
    _, proto = await self._create_direct_connection(req, traces, timeout)
  File "C:\Users\esaha\PycharmProjects\GIt\DiscordBot\venv\lib\site-packages\aiohttp\connector.py", line 1206, in _create_direct_connection
    raise last_exc
  File "C:\Users\esaha\PycharmProjects\GIt\DiscordBot\venv\lib\site-packages\aiohttp\connector.py", line 1175, in _create_direct_connection
    transp, proto = await self._wrap_create_connection(
  File "C:\Users\esaha\PycharmProjects\GIt\DiscordBot\venv\lib\site-packages\aiohttp\connector.py", line 992, in _wrap_create_connection
    raise client_error(req.connection_key, exc) from exc
aiohttp.client_exceptions.ClientConnectorError: Cannot connect to host discord.com:443 ssl:default [The semaphore timeout period has expired]
[2022-03-09 00:09:21,199: ERROR]: [discord.client]: Attempting a reconnect in 3.96s
Traceback (most recent call last):
  File "C:\Users\esaha\PycharmProjects\GIt\DiscordBot\venv\lib\site-packages\aiohttp\connector.py", line 986, in _wrap_create_connection
    return await self._loop.create_connection(*args, **kwargs)  # type: ignore[return-value]  # noqa
  File "C:\Users\esaha\AppData\Local\Programs\Python\Python39\lib\asyncio\base_events.py", line 1056, in create_connection
    raise exceptions[0]
  File "C:\Users\esaha\AppData\Local\Programs\Python\Python39\lib\asyncio\base_events.py", line 1041, in create_connection
    sock = await self._connect_sock(
  File "C:\Users\esaha\AppData\Local\Programs\Python\Python39\lib\asyncio\base_events.py", line 955, in _connect_sock
    await self.sock_connect(sock, address)
  File "C:\Users\esaha\AppData\Local\Programs\Python\Python39\lib\asyncio\proactor_events.py", line 702, in sock_connect
    return await self._proactor.connect(sock, address)
  File "C:\Users\esaha\AppData\Local\Programs\Python\Python39\lib\asyncio\windows_events.py", line 812, in _poll
    value = callback(transferred, key, ov)
  File "C:\Users\esaha\AppData\Local\Programs\Python\Python39\lib\asyncio\windows_events.py", line 599, in finish_connect
    ov.getresult()
OSError: [WinError 121] The semaphore timeout period has expired

The above exception was the direct cause of the following exception:

Traceback (most recent call last):
  File "C:\Users\esaha\PycharmProjects\GIt\DiscordBot\venv\lib\site-packages\discord\client.py", line 550, in connect
    self.ws = await asyncio.wait_for(coro, timeout=60.0)
  File "C:\Users\esaha\AppData\Local\Programs\Python\Python39\lib\asyncio\tasks.py", line 481, in wait_for
    return fut.result()
  File "C:\Users\esaha\PycharmProjects\GIt\DiscordBot\venv\lib\site-packages\discord\gateway.py", line 329, in from_client
    gateway = gateway or await client.http.get_gateway()
  File "C:\Users\esaha\PycharmProjects\GIt\DiscordBot\venv\lib\site-packages\discord\http.py", line 2453, in get_gateway
    data = await self.request(Route("GET", "/gateway"))
  File "C:\Users\esaha\PycharmProjects\GIt\DiscordBot\venv\lib\site-packages\discord\http.py", line 282, in request
    async with self.__session.request(method, url, **kwargs) as response:
  File "C:\Users\esaha\PycharmProjects\GIt\DiscordBot\venv\lib\site-packages\aiohttp\client.py", line 1138, in __aenter__
    self._resp = await self._coro
  File "C:\Users\esaha\PycharmProjects\GIt\DiscordBot\venv\lib\site-packages\aiohttp\client.py", line 535, in _request
    conn = await self._connector.connect(
  File "C:\Users\esaha\PycharmProjects\GIt\DiscordBot\venv\lib\site-packages\aiohttp\connector.py", line 542, in connect
    proto = await self._create_connection(req, traces, timeout)
  File "C:\Users\esaha\PycharmProjects\GIt\DiscordBot\venv\lib\site-packages\aiohttp\connector.py", line 907, in _create_connection
    _, proto = await self._create_direct_connection(req, traces, timeout)
  File "C:\Users\esaha\PycharmProjects\GIt\DiscordBot\venv\lib\site-packages\aiohttp\connector.py", line 1206, in _create_direct_connection
    raise last_exc
  File "C:\Users\esaha\PycharmProjects\GIt\DiscordBot\venv\lib\site-packages\aiohttp\connector.py", line 1175, in _create_direct_connection
    transp, proto = await self._wrap_create_connection(
  File "C:\Users\esaha\PycharmProjects\GIt\DiscordBot\venv\lib\site-packages\aiohttp\connector.py", line 992, in _wrap_create_connection
    raise client_error(req.connection_key, exc) from exc
aiohttp.client_exceptions.ClientConnectorError: Cannot connect to host discord.com:443 ssl:default [The semaphore timeout period has expired]
[2022-03-09 00:09:46,211: ERROR]: [discord.client]: Attempting a reconnect in 6.65s
Traceback (most recent call last):
  File "C:\Users\esaha\PycharmProjects\GIt\DiscordBot\venv\lib\site-packages\aiohttp\connector.py", line 986, in _wrap_create_connection
    return await self._loop.create_connection(*args, **kwargs)  # type: ignore[return-value]  # noqa
  File "C:\Users\esaha\AppData\Local\Programs\Python\Python39\lib\asyncio\base_events.py", line 1056, in create_connection
    raise exceptions[0]
  File "C:\Users\esaha\AppData\Local\Programs\Python\Python39\lib\asyncio\base_events.py", line 1041, in create_connection
    sock = await self._connect_sock(
  File "C:\Users\esaha\AppData\Local\Programs\Python\Python39\lib\asyncio\base_events.py", line 955, in _connect_sock
    await self.sock_connect(sock, address)
  File "C:\Users\esaha\AppData\Local\Programs\Python\Python39\lib\asyncio\proactor_events.py", line 702, in sock_connect
    return await self._proactor.connect(sock, address)
  File "C:\Users\esaha\AppData\Local\Programs\Python\Python39\lib\asyncio\windows_events.py", line 812, in _poll
    value = callback(transferred, key, ov)
  File "C:\Users\esaha\AppData\Local\Programs\Python\Python39\lib\asyncio\windows_events.py", line 599, in finish_connect
    ov.getresult()
OSError: [WinError 121] The semaphore timeout period has expired

The above exception was the direct cause of the following exception:

Traceback (most recent call last):
  File "C:\Users\esaha\PycharmProjects\GIt\DiscordBot\venv\lib\site-packages\discord\client.py", line 550, in connect
    self.ws = await asyncio.wait_for(coro, timeout=60.0)
  File "C:\Users\esaha\AppData\Local\Programs\Python\Python39\lib\asyncio\tasks.py", line 481, in wait_for
    return fut.result()
  File "C:\Users\esaha\PycharmProjects\GIt\DiscordBot\venv\lib\site-packages\discord\gateway.py", line 329, in from_client
    gateway = gateway or await client.http.get_gateway()
  File "C:\Users\esaha\PycharmProjects\GIt\DiscordBot\venv\lib\site-packages\discord\http.py", line 2453, in get_gateway
    data = await self.request(Route("GET", "/gateway"))
  File "C:\Users\esaha\PycharmProjects\GIt\DiscordBot\venv\lib\site-packages\discord\http.py", line 282, in request
    async with self.__session.request(method, url, **kwargs) as response:
  File "C:\Users\esaha\PycharmProjects\GIt\DiscordBot\venv\lib\site-packages\aiohttp\client.py", line 1138, in __aenter__
    self._resp = await self._coro
  File "C:\Users\esaha\PycharmProjects\GIt\DiscordBot\venv\lib\site-packages\aiohttp\client.py", line 535, in _request
    conn = await self._connector.connect(
  File "C:\Users\esaha\PycharmProjects\GIt\DiscordBot\venv\lib\site-packages\aiohttp\connector.py", line 542, in connect
    proto = await self._create_connection(req, traces, timeout)
  File "C:\Users\esaha\PycharmProjects\GIt\DiscordBot\venv\lib\site-packages\aiohttp\connector.py", line 907, in _create_connection
    _, proto = await self._create_direct_connection(req, traces, timeout)
  File "C:\Users\esaha\PycharmProjects\GIt\DiscordBot\venv\lib\site-packages\aiohttp\connector.py", line 1206, in _create_direct_connection
    raise last_exc
  File "C:\Users\esaha\PycharmProjects\GIt\DiscordBot\venv\lib\site-packages\aiohttp\connector.py", line 1175, in _create_direct_connection
    transp, proto = await self._wrap_create_connection(
  File "C:\Users\esaha\PycharmProjects\GIt\DiscordBot\venv\lib\site-packages\aiohttp\connector.py", line 992, in _wrap_create_connection
    raise client_error(req.connection_key, exc) from exc
aiohttp.client_exceptions.ClientConnectorError: Cannot connect to host discord.com:443 ssl:default [The semaphore timeout period has expired]
[2022-03-09 00:10:13,892: ERROR]: [discord.client]: Attempting a reconnect in 2.77s
Traceback (most recent call last):
  File "C:\Users\esaha\PycharmProjects\GIt\DiscordBot\venv\lib\site-packages\aiohttp\connector.py", line 986, in _wrap_create_connection
    return await self._loop.create_connection(*args, **kwargs)  # type: ignore[return-value]  # noqa
  File "C:\Users\esaha\AppData\Local\Programs\Python\Python39\lib\asyncio\base_events.py", line 1056, in create_connection
    raise exceptions[0]
  File "C:\Users\esaha\AppData\Local\Programs\Python\Python39\lib\asyncio\base_events.py", line 1041, in create_connection
    sock = await self._connect_sock(
  File "C:\Users\esaha\AppData\Local\Programs\Python\Python39\lib\asyncio\base_events.py", line 955, in _connect_sock
    await self.sock_connect(sock, address)
  File "C:\Users\esaha\AppData\Local\Programs\Python\Python39\lib\asyncio\proactor_events.py", line 702, in sock_connect
    return await self._proactor.connect(sock, address)
  File "C:\Users\esaha\AppData\Local\Programs\Python\Python39\lib\asyncio\windows_events.py", line 812, in _poll
    value = callback(transferred, key, ov)
  File "C:\Users\esaha\AppData\Local\Programs\Python\Python39\lib\asyncio\windows_events.py", line 599, in finish_connect
    ov.getresult()
OSError: [WinError 121] The semaphore timeout period has expired

The above exception was the direct cause of the following exception:

Traceback (most recent call last):
  File "C:\Users\esaha\PycharmProjects\GIt\DiscordBot\venv\lib\site-packages\discord\client.py", line 550, in connect
    self.ws = await asyncio.wait_for(coro, timeout=60.0)
  File "C:\Users\esaha\AppData\Local\Programs\Python\Python39\lib\asyncio\tasks.py", line 481, in wait_for
    return fut.result()
  File "C:\Users\esaha\PycharmProjects\GIt\DiscordBot\venv\lib\site-packages\discord\gateway.py", line 329, in from_client
    gateway = gateway or await client.http.get_gateway()
  File "C:\Users\esaha\PycharmProjects\GIt\DiscordBot\venv\lib\site-packages\discord\http.py", line 2453, in get_gateway
    data = await self.request(Route("GET", "/gateway"))
  File "C:\Users\esaha\PycharmProjects\GIt\DiscordBot\venv\lib\site-packages\discord\http.py", line 282, in request
    async with self.__session.request(method, url, **kwargs) as response:
  File "C:\Users\esaha\PycharmProjects\GIt\DiscordBot\venv\lib\site-packages\aiohttp\client.py", line 1138, in __aenter__
    self._resp = await self._coro
  File "C:\Users\esaha\PycharmProjects\GIt\DiscordBot\venv\lib\site-packages\aiohttp\client.py", line 535, in _request
    conn = await self._connector.connect(
  File "C:\Users\esaha\PycharmProjects\GIt\DiscordBot\venv\lib\site-packages\aiohttp\connector.py", line 542, in connect
    proto = await self._create_connection(req, traces, timeout)
  File "C:\Users\esaha\PycharmProjects\GIt\DiscordBot\venv\lib\site-packages\aiohttp\connector.py", line 907, in _create_connection
    _, proto = await self._create_direct_connection(req, traces, timeout)
  File "C:\Users\esaha\PycharmProjects\GIt\DiscordBot\venv\lib\site-packages\aiohttp\connector.py", line 1206, in _create_direct_connection
    raise last_exc
  File "C:\Users\esaha\PycharmProjects\GIt\DiscordBot\venv\lib\site-packages\aiohttp\connector.py", line 1175, in _create_direct_connection
    transp, proto = await self._wrap_create_connection(
  File "C:\Users\esaha\PycharmProjects\GIt\DiscordBot\venv\lib\site-packages\aiohttp\connector.py", line 992, in _wrap_create_connection
    raise client_error(req.connection_key, exc) from exc
aiohttp.client_exceptions.ClientConnectorError: Cannot connect to host discord.com:443 ssl:default [The semaphore timeout period has expired]
[2022-03-09 00:10:17,836: INFO]: [discord.gateway]: Shard ID None has sent the RESUME payload.
[2022-03-09 00:10:18,027: INFO]: [discord.gateway]: Shard ID None session has been invalidated.
[2022-03-09 00:10:18,216: INFO]: [discord.client]: Got a request to IDENTIFY the websocket.
[2022-03-09 00:10:24,150: INFO]: [discord.gateway]: Shard ID None has sent the IDENTIFY payload.
[2022-03-09 00:10:24,468: INFO]: [discord.gateway]: Shard ID None has connected to Gateway: ["gateway-prd-main-lspj",{"micros":126303,"calls":["discord-sessions-blue-prd-2-2",{"micros":125171,"calls":["start_session",{"micros":106294,"calls":["discord-api-c4585754c-t9chs",{"micros":99852,"calls":["get_user",{"micros":16516},"add_authorized_ip",{"micros":9006},"get_guilds",{"micros":14650},"coros_wait",{"micros":1}]}]},"guilds_connect",{"micros":1,"calls":[]},"presence_connect",{"micros":18214,"calls":[]}]}]}] (Session ID: a6dffc56f3204b3c76e65878cadfc1db).
[2022-03-09 00:15:49,323: INFO]: [discord.gateway]: Websocket closed with WSCloseCode.ABNORMAL_CLOSURE, attempting a reconnect.
[2022-03-09 00:15:49,323: INFO]: [discord.client]: Got a request to RESUME the websocket.
[2022-03-09 00:15:50,133: INFO]: [discord.gateway]: Shard ID None has sent the RESUME payload.
[2022-03-09 00:15:50,458: INFO]: [discord.gateway]: Shard ID None has successfully RESUMED session a6dffc56f3204b3c76e65878cadfc1db under trace ["gateway-prd-main-mqjt",{"micros":1010,"calls":["discord-sessions-blue-prd-2-2",{"micros":18}]}].
[2022-03-09 00:19:16,486: INFO]: [discord.gateway]: Websocket closed with WSCloseCode.ABNORMAL_CLOSURE, attempting a reconnect.
[2022-03-09 00:19:16,486: INFO]: [discord.client]: Got a request to RESUME the websocket.
[2022-03-09 00:19:17,228: INFO]: [discord.gateway]: Shard ID None has sent the RESUME payload.
[2022-03-09 00:19:17,415: INFO]: [discord.gateway]: Shard ID None has successfully RESUMED session a6dffc56f3204b3c76e65878cadfc1db under trace ["gateway-prd-main-t8rj",{"micros":579,"calls":["discord-sessions-blue-prd-2-2",{"micros":19}]}].
[2022-03-09 00:19:23,207: INFO]: [discord.client]: Received signal to terminate bot and event loop.
[2022-03-09 00:19:23,207: INFO]: [discord.client]: Cleaning up tasks.
[2022-03-09 00:19:23,207: INFO]: [discord.client]: Cleaning up after 2 tasks.
